MainThread 2017-04-18 16:19:14,521 image_match/ERROR/image_match.py:42:test_image_match_001:97821/-1523326528:{
    "msg": "Traceback (most recent call last):\n  File \"image_match.py\", line 40, in test_image_match_001\n    self.assertEqual(results['total'], 618)\n  File \"/System/Library/Frameworks/Python.framework/Versions/2.7/lib/python2.7/unittest/case.py\", line 515, in assertEqual\n    assertion_func(first, second, msg=msg)\n  File \"/System/Library/Frameworks/Python.framework/Versions/2.7/lib/python2.7/unittest/case.py\", line 508, in _baseAssertEqual\n    raise self.failureException(msg)\nAssertionError: 743 != 618\n"
}
MainThread 2017-04-19 16:43:06,151 image_match/ERROR/image_match.py:42:test_image_match_001:7017/-1523326528:{
    "msg": "Traceback (most recent call last):\n  File \"/Users/lazybone/workspaces/study_python/unittest/image_match.py\", line 40, in test_image_match_001\n    self.assertEqual(results['total'], 618)\n  File \"/System/Library/Frameworks/Python.framework/Versions/2.7/lib/python2.7/unittest/case.py\", line 515, in assertEqual\n    assertion_func(first, second, msg=msg)\n  File \"/System/Library/Frameworks/Python.framework/Versions/2.7/lib/python2.7/unittest/case.py\", line 508, in _baseAssertEqual\n    raise self.failureException(msg)\nAssertionError: 871 != 618\n"
}
MainThread 2017-04-19 16:43:06,634 image_match/ERROR/image_match.py:42:test_image_match_001:7020/-1523326528:{
    "msg": "Traceback (most recent call last):\n  File \"/Users/lazybone/workspaces/study_python/unittest/image_match.py\", line 40, in test_image_match_001\n    self.assertEqual(results['total'], 618)\n  File \"/System/Library/Frameworks/Python.framework/Versions/2.7/lib/python2.7/unittest/case.py\", line 515, in assertEqual\n    assertion_func(first, second, msg=msg)\n  File \"/System/Library/Frameworks/Python.framework/Versions/2.7/lib/python2.7/unittest/case.py\", line 508, in _baseAssertEqual\n    raise self.failureException(msg)\nAssertionError: 871 != 618\n"
}
MainThread 2017-04-20 16:25:21,574 image_match/ERROR/image_match.py:39:test_image_match_001:24020/-1523326528:{
    "msg": "Traceback (most recent call last):\n  File \"image_match.py\", line 39, in test_image_match_001\n    response = requests.request(\"POST\", url, headers=headers, params=querystring)\n  File \"/System/Library/Frameworks/Python.framework/Versions/2.7/lib/python2.7/unittest/case.py\", line 515, in assertEqual\n    assertion_func(first, second, msg=msg)\n  File \"/System/Library/Frameworks/Python.framework/Versions/2.7/lib/python2.7/unittest/case.py\", line 508, in _baseAssertEqual\n    raise self.failureException(msg)\nAssertionError: 815 != 618\n"
}
MainThread 2017-04-20 16:26:45,308 image_match/ERROR/image_match.py:39:test_image_match_001:24028/-1523326528:{
    "msg": "Traceback (most recent call last):\n  File \"image_match.py\", line 39, in test_image_match_001\n    response = requests.request(\"POST\", url, headers=headers, params=querystring)\n  File \"/System/Library/Frameworks/Python.framework/Versions/2.7/lib/python2.7/unittest/case.py\", line 515, in assertEqual\n    assertion_func(first, second, msg=msg)\n  File \"/System/Library/Frameworks/Python.framework/Versions/2.7/lib/python2.7/unittest/case.py\", line 508, in _baseAssertEqual\n    raise self.failureException(msg)\nAssertionError: 815 != 618\n"
}
MainThread 2017-04-20 16:28:35,393 image_match/ERROR/image_match.py:39:test_image_match_001:24045/-1523326528:{
    "msg": "Traceback (most recent call last):\n  File \"image_match.py\", line 39, in test_image_match_001\n    response = requests.request(\"POST\", url, headers=headers, params=querystring)\n  File \"/System/Library/Frameworks/Python.framework/Versions/2.7/lib/python2.7/unittest/case.py\", line 515, in assertEqual\n    assertion_func(first, second, msg=msg)\n  File \"/System/Library/Frameworks/Python.framework/Versions/2.7/lib/python2.7/unittest/case.py\", line 508, in _baseAssertEqual\n    raise self.failureException(msg)\nAssertionError: 816 != 618\n"
}
MainThread 2017-04-25 10:23:26,113 image_match/ERROR/image_match.py:50:test_image_match_001:34977/-1523326528:{
    "msg": "Traceback (most recent call last):\n  File \"/Users/lazybone/workspaces/study_python/unittest/image_match.py\", line 48, in test_image_match_001\n    self.assertEqual(results['total'], 618)\n  File \"/System/Library/Frameworks/Python.framework/Versions/2.7/lib/python2.7/unittest/case.py\", line 515, in assertEqual\n    assertion_func(first, second, msg=msg)\n  File \"/System/Library/Frameworks/Python.framework/Versions/2.7/lib/python2.7/unittest/case.py\", line 508, in _baseAssertEqual\n    raise self.failureException(msg)\nAssertionError: 299 != 618\n"
}
MainThread 2017-04-25 10:24:03,647 image_match/ERROR/image_match.py:50:test_image_match_001:34999/-1523326528:{
    "msg": "Traceback (most recent call last):\n  File \"image_match.py\", line 48, in test_image_match_001\n    self.assertEqual(results['total'], 618)\n  File \"/System/Library/Frameworks/Python.framework/Versions/2.7/lib/python2.7/unittest/case.py\", line 515, in assertEqual\n    assertion_func(first, second, msg=msg)\n  File \"/System/Library/Frameworks/Python.framework/Versions/2.7/lib/python2.7/unittest/case.py\", line 508, in _baseAssertEqual\n    raise self.failureException(msg)\nAssertionError: 299 != 618\n"
}
MainThread 2017-04-25 10:31:19,531 image_match/ERROR/image_match.py:50:test_image_match_001:35170/-1523326528:{
    "msg": "Traceback (most recent call last):\n  File \"/Users/lazybone/workspaces/study_python/unittest/image_match.py\", line 48, in test_image_match_001\n    self.assertEqual(results['total'], 618)\n  File \"/System/Library/Frameworks/Python.framework/Versions/2.7/lib/python2.7/unittest/case.py\", line 515, in assertEqual\n    assertion_func(first, second, msg=msg)\n  File \"/System/Library/Frameworks/Python.framework/Versions/2.7/lib/python2.7/unittest/case.py\", line 508, in _baseAssertEqual\n    raise self.failureException(msg)\nAssertionError: 320 != 618\n"
}
MainThread 2017-04-25 10:32:06,981 image_match/ERROR/image_match.py:50:test_image_match_001:35185/-1523326528:{
    "msg": "Traceback (most recent call last):\n  File \"/Users/lazybone/workspaces/study_python/unittest/image_match.py\", line 48, in test_image_match_001\n    self.assertEqual(results['total'], 618)\n  File \"/System/Library/Frameworks/Python.framework/Versions/2.7/lib/python2.7/unittest/case.py\", line 515, in assertEqual\n    assertion_func(first, second, msg=msg)\n  File \"/System/Library/Frameworks/Python.framework/Versions/2.7/lib/python2.7/unittest/case.py\", line 508, in _baseAssertEqual\n    raise self.failureException(msg)\nAssertionError: 320 != 618\n"
}
MainThread 2017-04-25 10:32:22,350 image_match/ERROR/image_match.py:50:test_image_match_001:35193/-1523326528:{
    "msg": "Traceback (most recent call last):\n  File \"image_match.py\", line 48, in test_image_match_001\n    self.assertEqual(results['total'], 618)\n  File \"/System/Library/Frameworks/Python.framework/Versions/2.7/lib/python2.7/unittest/case.py\", line 515, in assertEqual\n    assertion_func(first, second, msg=msg)\n  File \"/System/Library/Frameworks/Python.framework/Versions/2.7/lib/python2.7/unittest/case.py\", line 508, in _baseAssertEqual\n    raise self.failureException(msg)\nAssertionError: 320 != 618\n"
}
MainThread 2017-04-25 10:32:59,147 image_match/ERROR/image_match.py:50:test_image_match_001:35210/-1523326528:{
    "msg": "Traceback (most recent call last):\n  File \"/Users/lazybone/workspaces/study_python/unittest/image_match.py\", line 48, in test_image_match_001\n    self.assertEqual(results['total'], 618)\n  File \"/System/Library/Frameworks/Python.framework/Versions/2.7/lib/python2.7/unittest/case.py\", line 515, in assertEqual\n    assertion_func(first, second, msg=msg)\n  File \"/System/Library/Frameworks/Python.framework/Versions/2.7/lib/python2.7/unittest/case.py\", line 508, in _baseAssertEqual\n    raise self.failureException(msg)\nAssertionError: 321 != 618\n"
}
MainThread 2017-04-25 10:42:41,962 image_match/ERROR/image_match.py:47:test_image_match_001:35497/-1523326528:{
    "msg": "Traceback (most recent call last):\n  File \"/Users/lazybone/workspaces/study_python/unittest/image_match.py\", line 45, in test_image_match_001\n    except:\n  File \"/System/Library/Frameworks/Python.framework/Versions/2.7/lib/python2.7/unittest/case.py\", line 515, in assertEqual\n    assertion_func(first, second, msg=msg)\n  File \"/System/Library/Frameworks/Python.framework/Versions/2.7/lib/python2.7/unittest/case.py\", line 508, in _baseAssertEqual\n    raise self.failureException(msg)\nAssertionError: 334 != 618\n"
}
MainThread 2017-04-25 10:42:57,992 image_match/ERROR/image_match.py:46:test_image_match_001:35536/-1523326528:{
    "msg": "Traceback (most recent call last):\n  File \"image_match.py\", line 44, in test_image_match_001\n    self.assertEqual(results['total'], 618)\n  File \"/System/Library/Frameworks/Python.framework/Versions/2.7/lib/python2.7/unittest/case.py\", line 515, in assertEqual\n    assertion_func(first, second, msg=msg)\n  File \"/System/Library/Frameworks/Python.framework/Versions/2.7/lib/python2.7/unittest/case.py\", line 508, in _baseAssertEqual\n    raise self.failureException(msg)\nAssertionError: 336 != 618\n"
}
MainThread 2017-04-25 10:47:56,197 image_match/ERROR/image_match.py:63:test_image_match_001:35581/-1523326528:{
    "msg": "Traceback (most recent call last):\n  File \"/Users/lazybone/workspaces/study_python/unittest/image_match.py\", line 61, in test_image_match_001\n    self.assertEqual(results['total'], 618)\n  File \"/System/Library/Frameworks/Python.framework/Versions/2.7/lib/python2.7/unittest/case.py\", line 515, in assertEqual\n    assertion_func(first, second, msg=msg)\n  File \"/System/Library/Frameworks/Python.framework/Versions/2.7/lib/python2.7/unittest/case.py\", line 508, in _baseAssertEqual\n    raise self.failureException(msg)\nAssertionError: 342 != 618\n"
}
MainThread 2017-04-25 11:19:48,139 image_match/ERROR/image_match.py:50:test_image_match_001:36758/-1523326528:{
    "msg": "Traceback (most recent call last):\n  File \"/Users/lazybone/workspaces/study_python/unittest/image_match.py\", line 48, in test_image_match_001\n    self.assertEqual(results['total'], 618)\n  File \"/System/Library/Frameworks/Python.framework/Versions/2.7/lib/python2.7/unittest/case.py\", line 515, in assertEqual\n    assertion_func(first, second, msg=msg)\n  File \"/System/Library/Frameworks/Python.framework/Versions/2.7/lib/python2.7/unittest/case.py\", line 508, in _baseAssertEqual\n    raise self.failureException(msg)\nAssertionError: 403 != 618\n"
}
MainThread 2017-04-25 14:07:39,881 image_match/ERROR/image_match.py:67:test_image_match_001:37209/-1523326528:{
    "msg": "Traceback (most recent call last):\n  File \"/Users/lazybone/workspaces/study_python/unittest/image_match.py\", line 65, in test_image_match_001\n    self.assertEqual(results['total'], 618)\n  File \"/System/Library/Frameworks/Python.framework/Versions/2.7/lib/python2.7/unittest/case.py\", line 515, in assertEqual\n    assertion_func(first, second, msg=msg)\n  File \"/System/Library/Frameworks/Python.framework/Versions/2.7/lib/python2.7/unittest/case.py\", line 508, in _baseAssertEqual\n    raise self.failureException(msg)\nAssertionError: 646 != 618\n"
}
MainThread 2017-04-25 14:08:19,226 image_match/ERROR/image_match.py:67:test_image_match_001:37217/-1523326528:{
    "msg": "Traceback (most recent call last):\n  File \"/Users/lazybone/workspaces/study_python/unittest/image_match.py\", line 65, in test_image_match_001\n    self.assertEqual(results['total'], 618)\n  File \"/System/Library/Frameworks/Python.framework/Versions/2.7/lib/python2.7/unittest/case.py\", line 515, in assertEqual\n    assertion_func(first, second, msg=msg)\n  File \"/System/Library/Frameworks/Python.framework/Versions/2.7/lib/python2.7/unittest/case.py\", line 508, in _baseAssertEqual\n    raise self.failureException(msg)\nAssertionError: 646 != 618\n"
}
MainThread 2017-04-25 14:17:30,656 image_match/ERROR/image_match.py:67:test_image_match_001:37576/-1523326528:{
    "msg": "Traceback (most recent call last):\n  File \"/Users/lazybone/workspaces/study_python/unittest/image_match.py\", line 65, in test_image_match_001\n    self.assertEqual(results['total'], 618)\n  File \"/System/Library/Frameworks/Python.framework/Versions/2.7/lib/python2.7/unittest/case.py\", line 515, in assertEqual\n    assertion_func(first, second, msg=msg)\n  File \"/System/Library/Frameworks/Python.framework/Versions/2.7/lib/python2.7/unittest/case.py\", line 508, in _baseAssertEqual\n    raise self.failureException(msg)\nAssertionError: 662 != 618\n"
}
MainThread 2017-04-25 14:18:09,925 image_match/ERROR/image_match.py:67:test_image_match_001:37585/-1523326528:{
    "msg": "Traceback (most recent call last):\n  File \"/Users/lazybone/workspaces/study_python/unittest/image_match.py\", line 65, in test_image_match_001\n    self.assertEqual(results['total'], 618)\n  File \"/System/Library/Frameworks/Python.framework/Versions/2.7/lib/python2.7/unittest/case.py\", line 515, in assertEqual\n    assertion_func(first, second, msg=msg)\n  File \"/System/Library/Frameworks/Python.framework/Versions/2.7/lib/python2.7/unittest/case.py\", line 508, in _baseAssertEqual\n    raise self.failureException(msg)\nAssertionError: 663 != 618\n"
}
MainThread 2017-04-25 14:18:39,055 image_match/ERROR/image_match.py:67:test_image_match_001:37661/-1523326528:{
    "msg": "Traceback (most recent call last):\n  File \"image_match.py\", line 65, in test_image_match_001\n    self.assertEqual(results['total'], 618)\n  File \"/System/Library/Frameworks/Python.framework/Versions/2.7/lib/python2.7/unittest/case.py\", line 515, in assertEqual\n    assertion_func(first, second, msg=msg)\n  File \"/System/Library/Frameworks/Python.framework/Versions/2.7/lib/python2.7/unittest/case.py\", line 508, in _baseAssertEqual\n    raise self.failureException(msg)\nAssertionError: 663 != 618\n"
}
MainThread 2017-04-25 14:32:42,932 image_match/ERROR/image_match.py:66:test_image_match_001:37903/-1523326528:{
    "msg": "Traceback (most recent call last):\n  File \"image_match.py\", line 64, in test_image_match_001\n    self.assertEqual(results['total'], 618)\n  File \"/System/Library/Frameworks/Python.framework/Versions/2.7/lib/python2.7/unittest/case.py\", line 515, in assertEqual\n    assertion_func(first, second, msg=msg)\n  File \"/System/Library/Frameworks/Python.framework/Versions/2.7/lib/python2.7/unittest/case.py\", line 508, in _baseAssertEqual\n    raise self.failureException(msg)\nAssertionError: 670 != 618\n"
}
