MainThread 2017-04-18 16:19:14,521 image_match/ERROR/image_match.py:42:test_image_match_001:97821/-1523326528:{
    "msg": "Traceback (most recent call last):\n  File \"image_match.py\", line 40, in test_image_match_001\n    self.assertEqual(results['total'], 618)\n  File \"/System/Library/Frameworks/Python.framework/Versions/2.7/lib/python2.7/unittest/case.py\", line 515, in assertEqual\n    assertion_func(first, second, msg=msg)\n  File \"/System/Library/Frameworks/Python.framework/Versions/2.7/lib/python2.7/unittest/case.py\", line 508, in _baseAssertEqual\n    raise self.failureException(msg)\nAssertionError: 743 != 618\n"
}
MainThread 2017-04-19 16:43:06,151 image_match/ERROR/image_match.py:42:test_image_match_001:7017/-1523326528:{
    "msg": "Traceback (most recent call last):\n  File \"/Users/lazybone/workspaces/study_python/unittest/image_match.py\", line 40, in test_image_match_001\n    self.assertEqual(results['total'], 618)\n  File \"/System/Library/Frameworks/Python.framework/Versions/2.7/lib/python2.7/unittest/case.py\", line 515, in assertEqual\n    assertion_func(first, second, msg=msg)\n  File \"/System/Library/Frameworks/Python.framework/Versions/2.7/lib/python2.7/unittest/case.py\", line 508, in _baseAssertEqual\n    raise self.failureException(msg)\nAssertionError: 871 != 618\n"
}
MainThread 2017-04-19 16:43:06,634 image_match/ERROR/image_match.py:42:test_image_match_001:7020/-1523326528:{
    "msg": "Traceback (most recent call last):\n  File \"/Users/lazybone/workspaces/study_python/unittest/image_match.py\", line 40, in test_image_match_001\n    self.assertEqual(results['total'], 618)\n  File \"/System/Library/Frameworks/Python.framework/Versions/2.7/lib/python2.7/unittest/case.py\", line 515, in assertEqual\n    assertion_func(first, second, msg=msg)\n  File \"/System/Library/Frameworks/Python.framework/Versions/2.7/lib/python2.7/unittest/case.py\", line 508, in _baseAssertEqual\n    raise self.failureException(msg)\nAssertionError: 871 != 618\n"
}
